2025-03-25 10:04:33,552 - httpx - INFO - HTTP Request: POST https://api.telegram.org/bot7809849560:AAHPQF54KnIzWMvj09KBJ9tTCkBjWuUktyA/getMe "HTTP/1.1 200 OK"
2025-03-25 10:04:33,644 - httpx - INFO - HTTP Request: POST https://api.telegram.org/bot7809849560:AAHPQF54KnIzWMvj09KBJ9tTCkBjWuUktyA/deleteWebhook "HTTP/1.1 200 OK"
2025-03-25 10:04:33,644 - telegram.ext.Application - INFO - Application started
2025-03-25 10:04:33,888 - httpx - INFO - HTTP Request: POST https://api.telegram.org/bot7809849560:AAHPQF54KnIzWMvj09KBJ9tTCkBjWuUktyA/getUpdates "HTTP/1.1 200 OK"
2025-03-25 10:04:38,734 - httpx - INFO - HTTP Request: POST https://api.telegram.org/bot7809849560:AAHPQF54KnIzWMvj09KBJ9tTCkBjWuUktyA/getUpdates "HTTP/1.1 409 Conflict"
2025-03-25 10:04:38,735 - __main__ - ERROR - Ошибка при обработке обновления:
Traceback (most recent call last):
  File "/home/ubuntu/telega_env/lib/python3.12/site-packages/telegram/ext/_updater.py", line 750, in _network_loop_retry
    if not await do_action():
           ^^^^^^^^^^^^^^^^^
  File "/home/ubuntu/telega_env/lib/python3.12/site-packages/telegram/ext/_updater.py", line 744, in do_action
    return action_cb_task.result()
           ^^^^^^^^^^^^^^^^^^^^^^^
  File "/usr/lib/python3.12/asyncio/futures.py", line 203, in result
    raise self._exception.with_traceback(self._exception_tb)
  File "/usr/lib/python3.12/asyncio/tasks.py", line 314, in __step_run_and_handle_result
    result = coro.send(None)
             ^^^^^^^^^^^^^^^
  File "/home/ubuntu/telega_env/lib/python3.12/site-packages/telegram/ext/_updater.py", line 371, in polling_action_cb
    updates = await self.bot.get_updates(
              ^^^^^^^^^^^^^^^^^^^^^^^^^^^
  File "/home/ubuntu/telega_env/lib/python3.12/site-packages/telegram/ext/_extbot.py", line 650, in get_updates
    updates = await super().get_updates(
              ^^^^^^^^^^^^^^^^^^^^^^^^^^
  File "/home/ubuntu/telega_env/lib/python3.12/site-packages/telegram/_bot.py", line 4480, in get_updates
    await self._post(
  File "/home/ubuntu/telega_env/lib/python3.12/site-packages/telegram/_bot.py", line 619, in _post
    return await self._do_post(
           ^^^^^^^^^^^^^^^^^^^^
  File "/home/ubuntu/telega_env/lib/python3.12/site-packages/telegram/ext/_extbot.py", line 354, in _do_post
    return await super()._do_post(
           ^^^^^^^^^^^^^^^^^^^^^^^
  File "/home/ubuntu/telega_env/lib/python3.12/site-packages/telegram/_bot.py", line 648, in _do_post
    result = await request.post(
             ^^^^^^^^^^^^^^^^^^^
  File "/home/ubuntu/telega_env/lib/python3.12/site-packages/telegram/request/_baserequest.py", line 202, in post
    result = await self._request_wrapper(
             ^^^^^^^^^^^^^^^^^^^^^^^^^^^^
  File "/home/ubuntu/telega_env/lib/python3.12/site-packages/telegram/request/_baserequest.py", line 385, in _request_wrapper
    raise Conflict(message)
telegram.error.Conflict: Conflict: terminated by other getUpdates request; make sure that only one bot instance is running
2025-03-25 10:04:48,075 - httpx - INFO - HTTP Request: POST https://api.telegram.org/bot7809849560:AAHPQF54KnIzWMvj09KBJ9tTCkBjWuUktyA/getUpdates "HTTP/1.1 409 Conflict"
2025-03-25 10:04:48,075 - __main__ - ERROR - Ошибка при обработке обновления:
Traceback (most recent call last):
  File "/home/ubuntu/telega_env/lib/python3.12/site-packages/telegram/ext/_updater.py", line 750, in _network_loop_retry
    if not await do_action():
           ^^^^^^^^^^^^^^^^^
  File "/home/ubuntu/telega_env/lib/python3.12/site-packages/telegram/ext/_updater.py", line 744, in do_action
    return action_cb_task.result()
           ^^^^^^^^^^^^^^^^^^^^^^^
  File "/usr/lib/python3.12/asyncio/futures.py", line 203, in result
    raise self._exception.with_traceback(self._exception_tb)
  File "/usr/lib/python3.12/asyncio/tasks.py", line 314, in __step_run_and_handle_result
    result = coro.send(None)
             ^^^^^^^^^^^^^^^
  File "/home/ubuntu/telega_env/lib/python3.12/site-packages/telegram/ext/_updater.py", line 371, in polling_action_cb
    updates = await self.bot.get_updates(
              ^^^^^^^^^^^^^^^^^^^^^^^^^^^
  File "/home/ubuntu/telega_env/lib/python3.12/site-packages/telegram/ext/_extbot.py", line 650, in get_updates
    updates = await super().get_updates(
              ^^^^^^^^^^^^^^^^^^^^^^^^^^
  File "/home/ubuntu/telega_env/lib/python3.12/site-packages/telegram/_bot.py", line 4480, in get_updates
    await self._post(
  File "/home/ubuntu/telega_env/lib/python3.12/site-packages/telegram/_bot.py", line 619, in _post
    return await self._do_post(
           ^^^^^^^^^^^^^^^^^^^^
  File "/home/ubuntu/telega_env/lib/python3.12/site-packages/telegram/ext/_extbot.py", line 354, in _do_post
    return await super()._do_post(
           ^^^^^^^^^^^^^^^^^^^^^^^
  File "/home/ubuntu/telega_env/lib/python3.12/site-packages/telegram/_bot.py", line 648, in _do_post
    result = await request.post(
             ^^^^^^^^^^^^^^^^^^^
  File "/home/ubuntu/telega_env/lib/python3.12/site-packages/telegram/request/_baserequest.py", line 202, in post
    result = await self._request_wrapper(
             ^^^^^^^^^^^^^^^^^^^^^^^^^^^^
  File "/home/ubuntu/telega_env/lib/python3.12/site-packages/telegram/request/_baserequest.py", line 385, in _request_wrapper
    raise Conflict(message)
telegram.error.Conflict: Conflict: terminated by other getUpdates request; make sure that only one bot instance is running
2025-03-25 10:04:57,919 - httpx - INFO - HTTP Request: POST https://api.telegram.org/bot7809849560:AAHPQF54KnIzWMvj09KBJ9tTCkBjWuUktyA/getUpdates "HTTP/1.1 409 Conflict"
2025-03-25 10:04:57,919 - __main__ - ERROR - Ошибка при обработке обновления:
Traceback (most recent call last):
  File "/home/ubuntu/telega_env/lib/python3.12/site-packages/telegram/ext/_updater.py", line 750, in _network_loop_retry
    if not await do_action():
           ^^^^^^^^^^^^^^^^^
  File "/home/ubuntu/telega_env/lib/python3.12/site-packages/telegram/ext/_updater.py", line 744, in do_action
    return action_cb_task.result()
           ^^^^^^^^^^^^^^^^^^^^^^^
  File "/usr/lib/python3.12/asyncio/futures.py", line 203, in result
    raise self._exception.with_traceback(self._exception_tb)
  File "/usr/lib/python3.12/asyncio/tasks.py", line 314, in __step_run_and_handle_result
    result = coro.send(None)
             ^^^^^^^^^^^^^^^
  File "/home/ubuntu/telega_env/lib/python3.12/site-packages/telegram/ext/_updater.py", line 371, in polling_action_cb
    updates = await self.bot.get_updates(
              ^^^^^^^^^^^^^^^^^^^^^^^^^^^
  File "/home/ubuntu/telega_env/lib/python3.12/site-packages/telegram/ext/_extbot.py", line 650, in get_updates
    updates = await super().get_updates(
              ^^^^^^^^^^^^^^^^^^^^^^^^^^
  File "/home/ubuntu/telega_env/lib/python3.12/site-packages/telegram/_bot.py", line 4480, in get_updates
    await self._post(
  File "/home/ubuntu/telega_env/lib/python3.12/site-packages/telegram/_bot.py", line 619, in _post
    return await self._do_post(
           ^^^^^^^^^^^^^^^^^^^^
  File "/home/ubuntu/telega_env/lib/python3.12/site-packages/telegram/ext/_extbot.py", line 354, in _do_post
    return await super()._do_post(
           ^^^^^^^^^^^^^^^^^^^^^^^
  File "/home/ubuntu/telega_env/lib/python3.12/site-packages/telegram/_bot.py", line 648, in _do_post
    result = await request.post(
             ^^^^^^^^^^^^^^^^^^^
  File "/home/ubuntu/telega_env/lib/python3.12/site-packages/telegram/request/_baserequest.py", line 202, in post
    result = await self._request_wrapper(
             ^^^^^^^^^^^^^^^^^^^^^^^^^^^^
  File "/home/ubuntu/telega_env/lib/python3.12/site-packages/telegram/request/_baserequest.py", line 385, in _request_wrapper
    raise Conflict(message)
telegram.error.Conflict: Conflict: terminated by other getUpdates request; make sure that only one bot instance is running
2025-03-25 10:05:08,549 - httpx - INFO - HTTP Request: POST https://api.telegram.org/bot7809849560:AAHPQF54KnIzWMvj09KBJ9tTCkBjWuUktyA/getUpdates "HTTP/1.1 409 Conflict"
2025-03-25 10:05:08,550 - __main__ - ERROR - Ошибка при обработке обновления:
Traceback (most recent call last):
  File "/home/ubuntu/telega_env/lib/python3.12/site-packages/telegram/ext/_updater.py", line 750, in _network_loop_retry
    if not await do_action():
           ^^^^^^^^^^^^^^^^^
  File "/home/ubuntu/telega_env/lib/python3.12/site-packages/telegram/ext/_updater.py", line 744, in do_action
    return action_cb_task.result()
           ^^^^^^^^^^^^^^^^^^^^^^^
  File "/usr/lib/python3.12/asyncio/futures.py", line 203, in result
    raise self._exception.with_traceback(self._exception_tb)
  File "/usr/lib/python3.12/asyncio/tasks.py", line 314, in __step_run_and_handle_result
    result = coro.send(None)
             ^^^^^^^^^^^^^^^
  File "/home/ubuntu/telega_env/lib/python3.12/site-packages/telegram/ext/_updater.py", line 371, in polling_action_cb
    updates = await self.bot.get_updates(
              ^^^^^^^^^^^^^^^^^^^^^^^^^^^
  File "/home/ubuntu/telega_env/lib/python3.12/site-packages/telegram/ext/_extbot.py", line 650, in get_updates
    updates = await super().get_updates(
              ^^^^^^^^^^^^^^^^^^^^^^^^^^
  File "/home/ubuntu/telega_env/lib/python3.12/site-packages/telegram/_bot.py", line 4480, in get_updates
    await self._post(
  File "/home/ubuntu/telega_env/lib/python3.12/site-packages/telegram/_bot.py", line 619, in _post
    return await self._do_post(
           ^^^^^^^^^^^^^^^^^^^^
  File "/home/ubuntu/telega_env/lib/python3.12/site-packages/telegram/ext/_extbot.py", line 354, in _do_post
    return await super()._do_post(
           ^^^^^^^^^^^^^^^^^^^^^^^
  File "/home/ubuntu/telega_env/lib/python3.12/site-packages/telegram/_bot.py", line 648, in _do_post
    result = await request.post(
             ^^^^^^^^^^^^^^^^^^^
  File "/home/ubuntu/telega_env/lib/python3.12/site-packages/telegram/request/_baserequest.py", line 202, in post
    result = await self._request_wrapper(
             ^^^^^^^^^^^^^^^^^^^^^^^^^^^^
  File "/home/ubuntu/telega_env/lib/python3.12/site-packages/telegram/request/_baserequest.py", line 385, in _request_wrapper
    raise Conflict(message)
telegram.error.Conflict: Conflict: terminated by other getUpdates request; make sure that only one bot instance is running
2025-03-25 10:05:17,342 - httpx - INFO - HTTP Request: POST https://api.telegram.org/bot7809849560:AAHPQF54KnIzWMvj09KBJ9tTCkBjWuUktyA/getUpdates "HTTP/1.1 409 Conflict"
2025-03-25 10:05:17,343 - __main__ - ERROR - Ошибка при обработке обновления:
Traceback (most recent call last):
  File "/home/ubuntu/telega_env/lib/python3.12/site-packages/telegram/ext/_updater.py", line 750, in _network_loop_retry
    if not await do_action():
           ^^^^^^^^^^^^^^^^^
  File "/home/ubuntu/telega_env/lib/python3.12/site-packages/telegram/ext/_updater.py", line 744, in do_action
    return action_cb_task.result()
           ^^^^^^^^^^^^^^^^^^^^^^^
  File "/usr/lib/python3.12/asyncio/futures.py", line 203, in result
    raise self._exception.with_traceback(self._exception_tb)
  File "/usr/lib/python3.12/asyncio/tasks.py", line 314, in __step_run_and_handle_result
    result = coro.send(None)
             ^^^^^^^^^^^^^^^
  File "/home/ubuntu/telega_env/lib/python3.12/site-packages/telegram/ext/_updater.py", line 371, in polling_action_cb
    updates = await self.bot.get_updates(
              ^^^^^^^^^^^^^^^^^^^^^^^^^^^
  File "/home/ubuntu/telega_env/lib/python3.12/site-packages/telegram/ext/_extbot.py", line 650, in get_updates
    updates = await super().get_updates(
              ^^^^^^^^^^^^^^^^^^^^^^^^^^
  File "/home/ubuntu/telega_env/lib/python3.12/site-packages/telegram/_bot.py", line 4480, in get_updates
    await self._post(
  File "/home/ubuntu/telega_env/lib/python3.12/site-packages/telegram/_bot.py", line 619, in _post
    return await self._do_post(
           ^^^^^^^^^^^^^^^^^^^^
  File "/home/ubuntu/telega_env/lib/python3.12/site-packages/telegram/ext/_extbot.py", line 354, in _do_post
    return await super()._do_post(
           ^^^^^^^^^^^^^^^^^^^^^^^
  File "/home/ubuntu/telega_env/lib/python3.12/site-packages/telegram/_bot.py", line 648, in _do_post
    result = await request.post(
             ^^^^^^^^^^^^^^^^^^^
  File "/home/ubuntu/telega_env/lib/python3.12/site-packages/telegram/request/_baserequest.py", line 202, in post
    result = await self._request_wrapper(
             ^^^^^^^^^^^^^^^^^^^^^^^^^^^^
  File "/home/ubuntu/telega_env/lib/python3.12/site-packages/telegram/request/_baserequest.py", line 385, in _request_wrapper
    raise Conflict(message)
telegram.error.Conflict: Conflict: terminated by other getUpdates request; make sure that only one bot instance is running
2025-03-25 10:05:27,918 - httpx - INFO - HTTP Request: POST https://api.telegram.org/bot7809849560:AAHPQF54KnIzWMvj09KBJ9tTCkBjWuUktyA/getUpdates "HTTP/1.1 409 Conflict"
2025-03-25 10:05:27,919 - __main__ - ERROR - Ошибка при обработке обновления:
Traceback (most recent call last):
  File "/home/ubuntu/telega_env/lib/python3.12/site-packages/telegram/ext/_updater.py", line 750, in _network_loop_retry
    if not await do_action():
           ^^^^^^^^^^^^^^^^^
  File "/home/ubuntu/telega_env/lib/python3.12/site-packages/telegram/ext/_updater.py", line 744, in do_action
    return action_cb_task.result()
           ^^^^^^^^^^^^^^^^^^^^^^^
  File "/usr/lib/python3.12/asyncio/futures.py", line 203, in result
    raise self._exception.with_traceback(self._exception_tb)
  File "/usr/lib/python3.12/asyncio/tasks.py", line 314, in __step_run_and_handle_result
    result = coro.send(None)
             ^^^^^^^^^^^^^^^
  File "/home/ubuntu/telega_env/lib/python3.12/site-packages/telegram/ext/_updater.py", line 371, in polling_action_cb
    updates = await self.bot.get_updates(
              ^^^^^^^^^^^^^^^^^^^^^^^^^^^
  File "/home/ubuntu/telega_env/lib/python3.12/site-packages/telegram/ext/_extbot.py", line 650, in get_updates
    updates = await super().get_updates(
              ^^^^^^^^^^^^^^^^^^^^^^^^^^
  File "/home/ubuntu/telega_env/lib/python3.12/site-packages/telegram/_bot.py", line 4480, in get_updates
    await self._post(
  File "/home/ubuntu/telega_env/lib/python3.12/site-packages/telegram/_bot.py", line 619, in _post
    return await self._do_post(
           ^^^^^^^^^^^^^^^^^^^^
  File "/home/ubuntu/telega_env/lib/python3.12/site-packages/telegram/ext/_extbot.py", line 354, in _do_post
    return await super()._do_post(
           ^^^^^^^^^^^^^^^^^^^^^^^
  File "/home/ubuntu/telega_env/lib/python3.12/site-packages/telegram/_bot.py", line 648, in _do_post
    result = await request.post(
             ^^^^^^^^^^^^^^^^^^^
  File "/home/ubuntu/telega_env/lib/python3.12/site-packages/telegram/request/_baserequest.py", line 202, in post
    result = await self._request_wrapper(
             ^^^^^^^^^^^^^^^^^^^^^^^^^^^^
  File "/home/ubuntu/telega_env/lib/python3.12/site-packages/telegram/request/_baserequest.py", line 385, in _request_wrapper
    raise Conflict(message)
telegram.error.Conflict: Conflict: terminated by other getUpdates request; make sure that only one bot instance is running
2025-03-25 10:05:41,033 - httpx - INFO - HTTP Request: POST https://api.telegram.org/bot7809849560:AAHPQF54KnIzWMvj09KBJ9tTCkBjWuUktyA/getUpdates "HTTP/1.1 409 Conflict"
2025-03-25 10:05:41,033 - __main__ - ERROR - Ошибка при обработке обновления:
Traceback (most recent call last):
  File "/home/ubuntu/telega_env/lib/python3.12/site-packages/telegram/ext/_updater.py", line 750, in _network_loop_retry
    if not await do_action():
           ^^^^^^^^^^^^^^^^^
  File "/home/ubuntu/telega_env/lib/python3.12/site-packages/telegram/ext/_updater.py", line 744, in do_action
    return action_cb_task.result()
           ^^^^^^^^^^^^^^^^^^^^^^^
  File "/usr/lib/python3.12/asyncio/futures.py", line 203, in result
    raise self._exception.with_traceback(self._exception_tb)
  File "/usr/lib/python3.12/asyncio/tasks.py", line 314, in __step_run_and_handle_result
    result = coro.send(None)
             ^^^^^^^^^^^^^^^
  File "/home/ubuntu/telega_env/lib/python3.12/site-packages/telegram/ext/_updater.py", line 371, in polling_action_cb
    updates = await self.bot.get_updates(
              ^^^^^^^^^^^^^^^^^^^^^^^^^^^
  File "/home/ubuntu/telega_env/lib/python3.12/site-packages/telegram/ext/_extbot.py", line 650, in get_updates
    updates = await super().get_updates(
              ^^^^^^^^^^^^^^^^^^^^^^^^^^
  File "/home/ubuntu/telega_env/lib/python3.12/site-packages/telegram/_bot.py", line 4480, in get_updates
    await self._post(
  File "/home/ubuntu/telega_env/lib/python3.12/site-packages/telegram/_bot.py", line 619, in _post
    return await self._do_post(
           ^^^^^^^^^^^^^^^^^^^^
  File "/home/ubuntu/telega_env/lib/python3.12/site-packages/telegram/ext/_extbot.py", line 354, in _do_post
    return await super()._do_post(
           ^^^^^^^^^^^^^^^^^^^^^^^
  File "/home/ubuntu/telega_env/lib/python3.12/site-packages/telegram/_bot.py", line 648, in _do_post
    result = await request.post(
             ^^^^^^^^^^^^^^^^^^^
  File "/home/ubuntu/telega_env/lib/python3.12/site-packages/telegram/request/_baserequest.py", line 202, in post
    result = await self._request_wrapper(
             ^^^^^^^^^^^^^^^^^^^^^^^^^^^^
  File "/home/ubuntu/telega_env/lib/python3.12/site-packages/telegram/request/_baserequest.py", line 385, in _request_wrapper
    raise Conflict(message)
telegram.error.Conflict: Conflict: terminated by other getUpdates request; make sure that only one bot instance is running
2025-03-25 10:05:57,948 - httpx - INFO - HTTP Request: POST https://api.telegram.org/bot7809849560:AAHPQF54KnIzWMvj09KBJ9tTCkBjWuUktyA/getUpdates "HTTP/1.1 409 Conflict"
2025-03-25 10:05:57,949 - __main__ - ERROR - Ошибка при обработке обновления:
Traceback (most recent call last):
  File "/home/ubuntu/telega_env/lib/python3.12/site-packages/telegram/ext/_updater.py", line 750, in _network_loop_retry
    if not await do_action():
           ^^^^^^^^^^^^^^^^^
  File "/home/ubuntu/telega_env/lib/python3.12/site-packages/telegram/ext/_updater.py", line 744, in do_action
    return action_cb_task.result()
           ^^^^^^^^^^^^^^^^^^^^^^^
  File "/usr/lib/python3.12/asyncio/futures.py", line 203, in result
    raise self._exception.with_traceback(self._exception_tb)
  File "/usr/lib/python3.12/asyncio/tasks.py", line 314, in __step_run_and_handle_result
    result = coro.send(None)
             ^^^^^^^^^^^^^^^
  File "/home/ubuntu/telega_env/lib/python3.12/site-packages/telegram/ext/_updater.py", line 371, in polling_action_cb
    updates = await self.bot.get_updates(
              ^^^^^^^^^^^^^^^^^^^^^^^^^^^
  File "/home/ubuntu/telega_env/lib/python3.12/site-packages/telegram/ext/_extbot.py", line 650, in get_updates
    updates = await super().get_updates(
              ^^^^^^^^^^^^^^^^^^^^^^^^^^
  File "/home/ubuntu/telega_env/lib/python3.12/site-packages/telegram/_bot.py", line 4480, in get_updates
    await self._post(
  File "/home/ubuntu/telega_env/lib/python3.12/site-packages/telegram/_bot.py", line 619, in _post
    return await self._do_post(
           ^^^^^^^^^^^^^^^^^^^^
  File "/home/ubuntu/telega_env/lib/python3.12/site-packages/telegram/ext/_extbot.py", line 354, in _do_post
    return await super()._do_post(
           ^^^^^^^^^^^^^^^^^^^^^^^
  File "/home/ubuntu/telega_env/lib/python3.12/site-packages/telegram/_bot.py", line 648, in _do_post
    result = await request.post(
             ^^^^^^^^^^^^^^^^^^^
  File "/home/ubuntu/telega_env/lib/python3.12/site-packages/telegram/request/_baserequest.py", line 202, in post
    result = await self._request_wrapper(
             ^^^^^^^^^^^^^^^^^^^^^^^^^^^^
  File "/home/ubuntu/telega_env/lib/python3.12/site-packages/telegram/request/_baserequest.py", line 385, in _request_wrapper
    raise Conflict(message)
telegram.error.Conflict: Conflict: terminated by other getUpdates request; make sure that only one bot instance is running
2025-03-25 10:06:15,301 - httpx - INFO - HTTP Request: POST https://api.telegram.org/bot7809849560:AAHPQF54KnIzWMvj09KBJ9tTCkBjWuUktyA/getUpdates "HTTP/1.1 200 OK"
2025-03-25 10:06:15,302 - telegram.ext.Application - INFO - Application is stopping. This might take a moment.
2025-03-25 10:06:15,302 - telegram.ext.Application - INFO - Application.stop() complete
Бот запущен, ожидаю события...
Traceback (most recent call last):
  File "/home/ubuntu/2ushka_telegram_bot/bot.py", line 284, in <module>
    asyncio.run(main())
  File "/home/ubuntu/telega_env/lib/python3.12/site-packages/nest_asyncio.py", line 30, in run
    return loop.run_until_complete(task)
           ^^^^^^^^^^^^^^^^^^^^^^^^^^^^^
  File "/home/ubuntu/telega_env/lib/python3.12/site-packages/nest_asyncio.py", line 98, in run_until_complete
    return f.result()
           ^^^^^^^^^^
  File "/usr/lib/python3.12/asyncio/futures.py", line 203, in result
    raise self._exception.with_traceback(self._exception_tb)
  File "/usr/lib/python3.12/asyncio/tasks.py", line 314, in __step_run_and_handle_result
    result = coro.send(None)
             ^^^^^^^^^^^^^^^
  File "/home/ubuntu/2ushka_telegram_bot/bot.py", line 279, in main
    await app.run_polling()
          ^^^^^^^^^^^^^^^^^
  File "/home/ubuntu/telega_env/lib/python3.12/site-packages/telegram/ext/_application.py", line 868, in run_polling
    return self.__run(
           ^^^^^^^^^^^
  File "/home/ubuntu/telega_env/lib/python3.12/site-packages/telegram/ext/_application.py", line 1099, in __run
    loop.close()
  File "/usr/lib/python3.12/asyncio/unix_events.py", line 68, in close
    super().close()
  File "/usr/lib/python3.12/asyncio/selector_events.py", line 101, in close
    raise RuntimeError("Cannot close a running event loop")
RuntimeError: Cannot close a running event loop
